Workbook
Name Slicer_City_tier: #N/A
Name Slicer_Diabetes_Status1: #N/A
Name Slicer_Hospital_tier: #N/A
Name Slicer_NumberOfMajorSurgeries: #N/A
Name Slicer_State_ID: #N/A
Name Slicer_Weight_Status: #N/A

Sheet Customer Names
A1: Customer ID | B1: name
A2: Id1 | B2: Hawks, Ms. Kelly
A3: Id2 | B3: Lehner, Mr. Matthew D
A4: Id3 | B4: Lu, Mr. Phil
A5: Id4 | B5: Osborne, Ms. Kelsey
A6: Id5 | B6: Kadala, Ms. Kristyn
A7: Id6 | B7: Baker, Mr. Russell B.
A8: Id7 | B8: Macpherson, Mr. Scott
A9: Id8 | B9: Hallman, Mr. Stephen
A10: Id9 | B10: Moran, Mr. Patrick R.
A11: Id10 | B11: Benner, Ms. Brooke N.
A12: Id11 | B12: Fierro Vargas, Ms. Paola Andrea
... A2336: Id2335 | B2336: German, Mr. Aaron K

Sheet Medical Examinations
A1: Customer ID | B1: BMI | C1: HBA1C | D1: Heart Issues | E1: Any Transplants | F1: Cancer history | G1: NumberOfMajorSurgeries | H1: smoker
A2: Id1 | B2: 47.41 | C2: 7.47 | D2: No | E2: No | F2: No | G2: No major surgery | H2: yes
A3: Id2 | B3: 30.36 | C3: 5.77 | D3: No | E3: No | F3: No | G3: No major surgery | H3: yes
A4: Id3 | B4: 34.485 | C4: 11.87 | D4: yes | E4: No | F4: No | G4: 2 | H4: yes
A5: Id4 | B5: 38.095 | C5: 6.05 | D5: No | E5: No | F5: No | G5: No major surgery | H5: yes
A6: Id5 | B6: 35.53 | C6: 5.45 | D6: No | E6: No | F6: No | G6: No major surgery | H6: yes
A7: Id6 | B7: 32.8 | C7: 6.59 | D7: No | E7: No | F7: No | G7: No major surgery | H7: yes
A8: Id7 | B8: 36.4 | C8: 6.07 | D8: No | E8: No | F8: No | G8: No major surgery | H8: yes
A9: Id8 | B9: 36.96 | C9: 7.93 | D9: No | E9: No | F9: No | G9: 3 | H9: yes
A10: Id9 | B10: 41.14 | C10: 9.58 | D10: yes | E10: No | F10: Yes | G10: 1 | H10: yes
A11: Id10 | B11: 38.06 | C11: 10.79 | D11: No | E11: No | F11: No | G11: No major surgery | H11: yes
A12: Id11 | B12: 37.7 | C12: 5.96 | D12: yes | E12: No | F12: No | G12: 2 | H12: yes
A13: Id12 | B13: 42.13 | C13: 11.9 | D13: No | E13: No | F13: No | G13: No major surgery | H13: yes
A14: Id13 | B14: 40.92 | C14: 8.41 | D14: No | E14: No | F14: No | G14: No major surgery | H14: yes
A15: Id14 | B15: 40.565 | C15: 7.02 | D15: No | E15: No | F15: No | G15: No major surgery | H15: yes
A16: Id15 | B16: 36.385 | C16: 7.59 | D16: yes | E16: No | F16: No | G16: 2 | H16: yes
A17: Id16 | B17: 39.9 | C17: 11.32 | D17: No | E17: No | F17: No | G17: No major surgery | H17: yes
A18: Id17 | B18: 33.8 | C18: 7.67 | D18: No | E18: No | F18: No | G18: 3 | H18: yes
A19: Id18 | B19: 36.765 | C19: 7.29 | D19: yes | E19: No | F19: Yes | G19: 1 | H19: yes
A20: Id19 | B20: 36.955 | C20: 4.72 | D20: yes | E20: No | F20: No | G20: 1 | H20: yes
A21: Id20 | B21: 42.9 | C21: 11.41 | D21: No | E21: No | F21: No | G21: No major surgery | H21: yes
A22: Id21 | B22: 36.3 | C22: 11.5 | D22: yes | E22: No | F22: No | G22: 2 | H22: yes
A23: Id22 | B23: 32.2 | C23: 6.22 | D23: yes | E23: No | F23: No | G23: 2 | H23: yes
A24: Id23 | B24: 31.3 | C24: 11.38 | D24: No | E24: No | F24: No | G24: 3 | H24: yes
A25: Id24 | B25: 41.8 | C25: 7.89 | D25: yes | E25: No | F25: No | G25: 2 | H25: yes
A26: Id25 | B26: 35.09 | C26: 4.38 | D26: yes | E26: No | F26: No | G26: 2 | H26: yes
A27: Id26 | B27: 33.88 | C27: 7.01 | D27: No | E27: No | F27: No | G27: 3 | H27: yes
A28: Id27 | B28: 30.875 | C28: 11.88 | D28: No | E28: No | F28: No | G28: No major surgery | H28: yes
A29: Id28 | B29: 36.86 | C29: 5.19 | D29: yes | E29: No | F29: Yes | G29: 1 | H29: yes
A30: Id29 | B30: 35.86 | C30: 6.74 | D30: yes | E30: No | F30: No | G30: 2 | H30: yes
A31: Id30 | B31: 37.05 | C31: 8.44 | D31: No | E31: No | F31: No | G31: No major surgery | H31: yes
A32: Id31 | B32: 43.89 | C32: 8.71 | D32: No | E32: No | F32: No | G32: No major surgery | H32: yes
A33: Id32 | B33: 42.35 | C33: 5.08 | D33: yes | E33: No | F33: No | G33: No major surgery | H33: yes
A34: Id33 | B34: 31.35 | C34: 6.86 | D34: No | E34: No | F34: No | G34: No major surgery | H34: yes
A35: Id34 | B35: 47.6 | C35: 5.95 | D35: yes | E35: No | F35: No | G35: No major surgery | H35: yes
A36: Id35 | B36: 46.2 | C36: 6.09 | D36: No | E36: No | F36: Yes | G36: 1 | H36: yes
A37: Id36 | B37: 32.015 | C37: 11.75 | D37: No | E37: No | F37: No | G37: No major surgery | H37: yes
A38: Id37 | B38: 40.565 | C38: 7.37 | D38: No | E38: No | F38: No | G38: No major surgery | H38: yes
A39: Id38 | B39: 32.45 | C39: 11.91 | D39: No | E39: No | F39: No | G39: No major surgery | H39: yes
A40: Id39 | B40: 34.96 | C40: 6.52 | D40: No | E40: No | F40: No | G40: No major surgery | H40: yes
...

Sheet Hospitalisation Details
A1: Customer ID | B1: year | C1: month | D1: date | E1: children | F1: charges | G1: Hospital tier | H1: City tier | I1: State ID
A2: Id2335 | B2: 1992 | C2: Jul | D2: 9 | E2: 0 | F2: 563.84 | G2: tier - 2 | H2: tier - 3 | I2: R1013
A3: Id2334 | B3: 1992 | C3: Nov | D3: 30 | E3: 0 | F3: 570.62 | G3: tier - 2 | H3: tier - 1 | I3: R1013
A4: Id2333 | B4: 1993 | C4: Jun | D4: 30 | E4: 0 | F4: 600 | G4: tier - 2 | H4: tier - 1 | I4: R1013
A5: Id2332 | B5: 1992 | C5: Sep | D5: 13 | E5: 0 | F5: 604.54 | G5: tier - 3 | H5: tier - 3 | I5: R1013
A6: Id2331 | B6: 1998 | C6: Jul | D6: 27 | E6: 0 | F6: 637.26 | G6: tier - 3 | H6: tier - 3 | I6: R1013
A7: Id2330 | B7: 2001 | C7: Nov | D7: 20 | E7: 0 | F7: 646.14 | G7: tier - 3 | H7: tier - 3 | I7: R1012
A8: Id2329 | B8: 1993 | C8: Jun | D8: 1 | E8: 0 | F8: 650 | G8: tier - 3 | H8: tier - 3 | I8: R1013
A9: Id2328 | B9: 1995 | C9: Jul | D9: 4 | E9: 0 | F9: 650 | G9: tier - 3 | H9: tier - 3 | I9: R1013
A10: Id2327 | B10: 2002 | C10: Nov | D10: 29 | E10: 0 | F10: 668 | G10: tier - 3 | H10: tier - 2 | I10: R1012
A11: Id2326 | B11: 1997 | C11: Nov | D11: 9 | E11: 0 | F11: 670 | G11: tier - 3 | H11: tier - 3 | I11: R1013
A12: Id2325 | B12: 2001 | C12: Sep | D12: 12 | E12: 0 | F12: 687.54 | G12: tier - 3 | H12: tier - 2 | I12: R1013
A13: Id2324 | B13: 1999 | C13: Dec | D13: 26 | E13: 0 | F13: 700 | G13: ? | H13: tier - 3 | I13: R1013
... A1050: Id1290 | B1050: 1977 | C1050: Jul | D1050: 26 | E1050: 2 | F1050: 8527.53 | G1050: tier - 2 | H1050: tier - 2 | I1050: R1013
A1051: Id1289 | B1051: ? | C1051: Jul | D1051: 24 | E1051: 0 | F1051: 8534.67 | G1051: tier - 2 | H1051: tier - 3 | I1051: R1024
A1052: Id1288 | B1052: 1981 | C1052: Dec | D1052: 27 | E1052: 3 | F1052: 8538.29 | G1052: tier - 2 | H1052: tier - 3 | I1052: R1024
A1053: Id1287 | B1053: 1975 | C1053: Nov | D1053: 6 | E1053: 1 | F1053: 8539.67 | G1053: tier - 2 | H1053: tier - 3 | I1053: R1011
A1054: Id1286 | B1054: ? | C1054: Dec | D1054: 12 | E1054: 1 | F1054: 8547.69 | G1054: tier - 2 | H1054: tier - 1 | I1054: R1013
A1055: Id1285 | B1055: 1975 | C1055: Aug | D1055: 6 | E1055: 1 | F1055: 8551.35 | G1055: tier - 2 | H1055: tier - 2 | I1055: R1011
A1056: Id1284 | B1056: 1975 | C1056: Aug | D1056: 21 | E1056: 1 | F1056: 8556.91 | G1056: tier - 2 | H1056: tier - 1 | I1056: R1011
A1057: Id1283 | B1057: 1988 | C1057: Sep | D1057: 21 | E1057: 3 | F1057: 8567.25 | G1057: tier - 2 | H1057: tier - 1 | I1057: R1012
A1058: Id1282 | B1058: 1975 | C1058: Sep | D1058: 26 | E1058: 1 | F1058: 8569.86 | G1058: tier - 2 | H1058: tier - 3 | I1058: R1013
A1059: Id1281 | B1059: 1982 | C1059: Dec | D1059: 6 | E1059: 3 | F1059: 8572.04 | G1059: tier - 2 | H1059: tier - 2 | I1059: R1021
A1060: Id1280 | B1060: 1987 | C1060: Nov | D1060: 11 | E1060: 3 | F1060: 8573.3 | G1060: tier - 2 | H1060: tier - 2 | I1060: R1021
A1061: Id1279 | B1061: 1983 | C1061: Dec | D1061: 30 | E1061: 5 | F1061: 8582.3 | G1061: tier - 2 | H1061: tier - 1 | I1061: R1013
A1062: Id1278 | B1062: 1983 | C1062: Jul | D1062: 25 | E1062: 5 | F1062: 8596.83 | G1062: tier - 2 | H1062: tier - 3 | I1062: R1013
A1063: Id1277 | B1063: 1973 | C1063: Jul | D1063: 11 | E1063: 0 | F1063: 8601.33 | G1063: tier - 2 | H1063: tier - 1 | I1063: R1013
A1064: Id1276 | B1064: 1977 | C1064: Sep | D1064: 24 | E1064: 2 | F1064: 8603.82 | G1064: tier - 2 | H1064: tier - 1 | I1064: R1019
A1065: Id1275 | B1065: 1977 | C1065: Nov | D1065: 12 | E1065: 2 | F1065: 8604.48 | G1065: tier - 3 | H1065: tier - 2 | I1065: R1016
A1066: Id1274 | B1066: 1977 | C1066: Oct | D1066: 15 | E1066: 3 | F1066: 8605.36 | G1066: tier - 2 | H1066: tier - 2 | I1066: R1013
... A2344: Id1 | B2344: 1968 | C2344: Oct | D2344: 12 | E2344: 0 | F2344: 63770.43 | G2344: tier - 1 | H2344: tier - 3 | I2344: R1013

Sheet Answer Data Cleaning
A1: Sl No | B1: 1 | K1: 2 | P1: 3 | R1: 4 | AA1: 3 | AC1: 3
J2: Average of year | K2: =AVERAGE('Hospitalisation Details'!B2:B23440) -> 1982.8415
B3: Number of missing values marked with '?' in each column of the “Medical Examinations” Table | F3: Number of missing values marked with '?' in each column of the"Hospitalization Details" Table. | J3: Customer ID | K3: year | L3: month | M3: date | N3: children | O3: charges | P3: Hospital tier | Q3: City tier | R3: State ID | T3: Customer ID | U3: BMI | V3: HBA1C | W3: Heart Issues | X3: Any Transplants | Y3: Cancer history | Z3: NumberOfMajorSurgeries | AA3: smoker | AC3: Most frequently occurring values in Smoker is "No"
B4: Column Name | C4: Number of Missing Value | F4: Column Name | G4: Number of Missing Value | J4: Id2335 | K4: 1992 | L4: Jul | M4: 9 | N4: 0 | O4: 563.84 | P4: tier - 2 | Q4: tier - 3 | R4: =IF('Hospitalisation Details'!I2="?","Unknown",'Hospitalisation Details'!I2) -> R1013 | T4: Id1 | U4: 47.41 | V4: 7.47 | W4: No | X4: No | Y4: No | Z4: No major surgery | AA4: yes | AC4: Column Name | AD4: Count of "Yes" | AE4: Count Of "No"
B5: Customer ID | C5: =COUNTIF('Medical Examinations'!A2:A2336,"?") -> 0 | F5: Customer ID | G5: =COUNTIF('Hospitalisation Details'!A2:A2344,"?") -> 6 | J5: Id2334 | K5: 1992 | L5: Nov | M5: 30 | N5: 0 | O5: 570.62 | P5: tier - 2 | Q5: tier - 1 | R5: =IF('Hospitalisation Details'!I3="?","Unknown",'Hospitalisation Details'!I3) -> R1013 | T5: Id2 | U5: 30.36 | V5: 5.77 | W5: No | X5: No | Y5: No | Z5: No major surgery | AA5: yes | AC5: smoker | AD5: =COUNTIF('Medical Examinations'!$H2:$H2336,"yes") -> 488 | AE5: =COUNTIF('Medical Examinations'!$H2:$H2336,"No") -> 1845
B6: BMI | C6: =COUNTIF('Medical Examinations'!B2:B2336,"?") -> 0 | F6: year | G6: =COUNTIF('Hospitalisation Details'!B2:B2344,"?") -> 2 | J6: Id2333 | K6: 1993 | L6: Jun | M6: 30 | N6: 0 | O6: 600 | P6: tier - 2 | Q6: tier - 1 | R6: =IF('Hospitalisation Details'!I4="?","Unknown",'Hospitalisation Details'!I4) -> R1013 | T6: Id3 | U6: 34.485 | V6: 11.87 | W6: yes | X6: No | Y6: No | Z6: 2 | AA6: yes
B7: HBA1C | C7: =COUNTIF('Medical Examinations'!C2:C2336,"?") -> 0 | F7: month | G7: =COUNTIF('Hospitalisation Details'!C2:C2344,"?") -> 3 | J7: Id2332 | K7: 1992 | L7: Sep | M7: 13 | N7: 0 | O7: 604.54 | P7: tier - 3 | Q7: tier - 3 | R7: =IF('Hospitalisation Details'!I5="?","Unknown",'Hospitalisation Details'!I5) -> R1013 | T7: Id4 | U7: 38.095 | V7: 6.05 | W7: No | X7: No | Y7: No | Z7: No major surgery | AA7: yes | AC7: Most frequently occurring values in Hospital tier is tier - 2 and City tier is tier - 2
B8: Heart Issues | C8: =COUNTIF('Medical Examinations'!D2:D2336,"?") -> 0 | F8: date | G8: =COUNTIF('Hospitalisation Details'!D2:D2344,"?") -> 0 | J8: Id2331 | K8: 1998 | L8: Jul | M8: 27 | N8: 0 | O8: 637.26 | P8: tier - 3 | Q8: tier - 3 | R8: =IF('Hospitalisation Details'!I6="?","Unknown",'Hospitalisation Details'!I6) -> R1013 | T8: Id5 | U8: 35.53 | V8: 5.45 | W8: No | X8: No | Y8: No | Z8: No major surgery | AA8: yes
B9: Any Transplants | C9: =COUNTIF('Medical Examinations'!E2:E2336,"?") -> 0 | F9: children | G9: =COUNTIF('Hospitalisation Details'!E2:E2344,"?") -> 0 | J9: Id2330 | K9: 2001 | L9: Nov | M9: 20 | N9: 0 | O9: 646.14 | P9: tier - 3 | Q9: tier - 3 | R9: =IF('Hospitalisation Details'!I7="?","Unknown",'Hospitalisation Details'!I7) -> R1012 | T9: Id6 | U9: 32.8 | V9: 6.59 | W9: No | X9: No | Y9: No | Z9: No major surgery | AA9: yes | AC9: Column Name | AD9: Count of tier - 1 | AE9: Count of tier - 2 | AF9: Count of tier - 3
B10: Cancer history | C10: =COUNTIF('Medical Examinations'!F2:F2336,"?") -> 0 | F10: charges | G10: =COUNTIF('Hospitalisation Details'!F2:F2344,"?") -> 0 | J10: Id2329 | K10: 1993 | L10: Jun | M10: 1 | N10: 0 | O10: 650 | P10: tier - 3 | Q10: tier - 3 | R10: =IF('Hospitalisation Details'!I8="?","Unknown",'Hospitalisation Details'!I8) -> R1013 | T10: Id7 | U10: 36.4 | V10: 6.07 | W10: No | X10: No | Y10: No | Z10: No major surgery | AA10: yes | AC10: Hospital tier | AD10: =COUNTIF('Hospitalisation Details'!$G2:$G2344,"tier - 1") -> 309 | AE10: =COUNTIF('Hospitalisation Details'!$G2:$G2344,"tier - 2") -> 1339 | AF10: =COUNTIF('Hospitalisation Details'!$G2:$G2344,"tier - 3") -> 694
B11: NumberOfMajorSurgeries | C11: =COUNTIF('Medical Examinations'!G2:G2336,"?") -> 0 | F11: Hospital tier | G11: =COUNTIF('Hospitalisation Details'!G2:G2344,"?") -> 1 | J11: Id2328 | K11: 1995 | L11: Jul | M11: 4 | N11: 0 | O11: 650 | P11: tier - 3 | Q11: tier - 3 | R11: =IF('Hospitalisation Details'!I9="?","Unknown",'Hospitalisation Details'!I9) -> R1013 | T11: Id8 | U11: 36.96 | V11: 7.93 | W11: No | X11: No | Y11: No | Z11: 3 | AA11: yes | AC11: City tier | AD11: =COUNTIF('Hospitalisation Details'!$H2:$H2344,"tier - 1") -> 734 | AE11: =COUNTIF('Hospitalisation Details'!$H2:$H2344,"tier - 2") -> 812 | AF11: =COUNTIF('Hospitalisation Details'!$H2:$H2344,"tier - 3") -> 796
B12: smoker | C12: =COUNTIF('Medical Examinations'!H2:H2336,"?") -> 2 | F12: City tier | G12: =COUNTIF('Hospitalisation Details'!H2:H2344,"?") -> 1 | J12: Id2327 | K12: 2002 | L12: Nov | M12: 29 | N12: 0 | O12: 668 | P12: tier - 3 | Q12: tier - 2 | R12: =IF('Hospitalisation Details'!I10="?","Unknown",'Hospitalisation Details'!I10) -> R1012 | T12: Id9 | U12: 41.14 | V12: 9.58 | W12: yes | X12: No | Y12: Yes | Z12: 1 | AA12: yes
F13: State ID | G13: =COUNTIF('Hospitalisation Details'!I2:I2344,"?") -> 2 | J13: Id2326 | K13: 1997 | L13: Nov | M13: 9 | N13: 0 | O13: 670 | P13: tier - 3 | Q13: tier - 3 | R13: =IF('Hospitalisation Details'!I11="?","Unknown",'Hospitalisation Details'!I11) -> R1013 | T13: Id10 | U13: 38.06 | V13: 10.79 | W13: No | X13: No | Y13: No | Z13: No major surgery | AA13: yes
J14: Id2325 | K14: 2001 | L14: Sep | M14: 12 | N14: 0 | O14: 687.54 | P14: tier - 3 | Q14: tier - 2 | R14: =IF('Hospitalisation Details'!I12="?","Unknown",'Hospitalisation Details'!I12) -> R1013 | T14: Id11 | U14: 37.7 | V14: 5.96 | W14: yes | X14: No | Y14: No | Z14: 2 | AA14: yes
J15: Id2324 | K15: 1999 | L15: Dec | M15: 26 | N15: 0 | O15: 700 | P15: tier - 2 | Q15: tier - 3 | R15: =IF('Hospitalisation Details'!I13="?","Unknown",'Hospitalisation Details'!I13) -> R1013 | T15: Id12 | U15: 42.13 | V15: 11.9 | W15: No | X15: No | Y15: No | Z15: No major surgery | AA15: yes
J16: Id2323 | K16: 1999 | L16: Dec | M16: 14 | N16: 0 | O16: 722.99 | P16: tier - 3 | Q16: tier - 1 | R16: =IF('Hospitalisation Details'!I14="?","Unknown",'Hospitalisation Details'!I14) -> R1013 | T16: Id13 | U16: 40.92 | V16: 8.41 | W16: No | X16: No | Y16: No | Z16: No major surgery | AA16: yes
J17: Id2322 | K17: 2002 | L17: Sep | M17: 19 | N17: 0 | O17: 750 | P17: tier - 3 | Q17: tier - 1 | R17: =IF('Hospitalisation Details'!I15="?","Unknown",'Hospitalisation Details'!I15) -> R1012 | T17: Id14 | U17: 40.565 | V17: 7.02 | W17: No | X17: No | Y17: No | Z17: No major surgery | AA17: yes
J18: Id2321 | K18: 1993 | L18: Aug | M18: 9 | N18: 0 | O18: 760 | P18: tier - 3 | Q18: tier - 1 | R18: =IF('Hospitalisation Details'!I16="?","Unknown",'Hospitalisation Details'!I16) -> R1013 | T18: Id15 | U18: 36.385 | V18: 7.59 | W18: yes | X18: No | Y18: No | Z18: 2 | AA18: yes
A19: 2 | J19: Id2320 | K19: 1996 | L19: Oct | M19: 22 | N19: 0 | O19: 760 | P19: tier - 3 | Q19: tier - 3 | R19: =IF('Hospitalisation Details'!I17="?","Unknown",'Hospitalisation Details'!I17) -> R1013 | T19: Id16 | U19: 39.9 | V19: 11.32 | W19: No | X19: No | Y19: No | Z19: No major surgery | AA19: yes
J20: Id2319 | K20: 1993 | L20: Jun | M20: 28 | N20: 0 | O20: 770 | P20: tier - 3 | Q20: tier - 3 | R20: =IF('Hospitalisation Details'!I18="?","Unknown",'Hospitalisation Details'!I18) -> R1013 | T20: Id17 | U20: 33.8 | V20: 7.67 | W20: No | X20: No | Y20: No | Z20: 3 | AA20: yes
J21: Id2318 | K21: 1996 | L21: Sep | M21: 18 | N21: 0 | O21: 770.38 | P21: tier - 3 | Q21: tier - 2 | R21: =IF('Hospitalisation Details'!I19="?","Unknown",'Hospitalisation Details'!I19) -> R1012 | T21: Id18 | U21: 36.765 | V21: 7.29 | W21: yes | X21: No | Y21: Yes | Z21: 1 | AA21: yes
J22: Id2317 | K22: 1995 | L22: Dec | M22: 7 | N22: 0 | O22: 773.54 | P22: tier - 3 | Q22: tier - 2 | R22: =IF('Hospitalisation Details'!I20="?","Unknown",'Hospitalisation Details'!I20) -> R1013 | T22: Id19 | U22: 36.955 | V22: 4.72 | W22: yes | X22: No | Y22: No | Z22: 1 | AA22: yes
J23: Id2316 | K23: 2004 | L23: Oct | M23: 7 | N23: 0 | O23: 830.52 | P23: tier - 3 | Q23: tier - 2 | R23: =IF('Hospitalisation Details'!I21="?","Unknown",'Hospitalisation Details'!I21) -> R1011 | T23: Id20 | U23: 42.9 | V23: 11.41 | W23: No | X23: No | Y23: No | Z23: No major surgery | AA23: yes
J24: Id2315 | K24: 2000 | L24: Nov | M24: 18 | N24: 0 | O24: 865.41 | P24: tier - 3 | Q24: tier - 1 | R24: =IF('Hospitalisation Details'!I22="?","Unknown",'Hospitalisation Details'!I22) -> R1013 | T24: Id21 | U24: 36.3 | V24: 11.5 | W24: yes | X24: No | Y24: No | Z24: 2 | AA24: yes
J25: Id2314 | K25: 1993 | L25: Nov | M25: 27 | N25: 0 | O25: 896.21 | P25: tier - 3 | Q25: tier - 1 | R25: =IF('Hospitalisation Details'!I23="?","Unknown",'Hospitalisation Details'!I23) -> R1013 | T25: Id22 | U25: 32.2 | V25: 6.22 | W25: yes | X25: No | Y25: No | Z25: 2 | AA25: yes
J26: Id2313 | K26: 1994 | L26: Oct | M26: 30 | N26: 0 | O26: 915.07 | P26: tier - 3 | Q26: tier - 1 | R26: =IF('Hospitalisation Details'!I24="?","Unknown",'Hospitalisation Details'!I24) -> R1013 | T26: Id23 | U26: 31.3 | V26: 11.38 | W26: No | X26: No | Y26: No | Z26: 3 | AA26: yes
J27: Id2312 | K27: 1995 | L27: Oct | M27: 28 | N27: 0 | O27: 928.59 | P27: tier - 3 | Q27: tier - 1 | R27: =IF('Hospitalisation Details'!I25="?","Unknown",'Hospitalisation Details'!I25) -> R1013 | T27: Id24 | U27: 41.8 | V27: 7.89 | W27: yes | X27: No | Y27: No | Z27: 2 | AA27: yes
J28: Id2311 | K28: 2001 | L28: Aug | M28: 19 | N28: 0 | O28: 964.71 | P28: tier - 3 | Q28: tier - 2 | R28: =IF('Hospitalisation Details'!I26="?","Unknown",'Hospitalisation Details'!I26) -> R1013 | T28: Id25 | U28: 35.09 | V28: 4.38 | W28: yes | X28: No | Y28: No | Z28: 2 | AA28: yes
J29: Id2310 | K29: 1994 | L29: Nov | M29: 22 | N29: 0 | O29: 1006.65 | P29: tier - 3 | Q29: tier - 2 | R29: =IF('Hospitalisation Details'!I27="?","Unknown",'Hospitalisation Details'!I27) -> R1013 | T29: Id26 | U29: 33.88 | V29: 7.01 | W29: No | X29: No | Y29: No | Z29: 3 | AA29: yes
J30: Id2309 | K30: 2000 | L30: Oct | M30: 9 | N30: 0 | O30: 1012 | P30: tier - 3 | Q30: tier - 2 | R30: =IF('Hospitalisation Details'!I28="?","Unknown",'Hospitalisation Details'!I28) -> R1013 | T30: Id27 | U30: 30.875 | V30: 11.88 | W30: No | X30: No | Y30: No | Z30: No major surgery | AA30: yes
J31: Id2308 | K31: 1999 | L31: Aug | M31: 5 | N31: 0 | O31: 1019 | P31: tier - 3 | Q31: tier - 2 | R31: =IF('Hospitalisation Details'!I29="?","Unknown",'Hospitalisation Details'!I29) -> R1013 | T31: Id28 | U31: 36.86 | V31: 5.19 | W31: yes | X31: No | Y31: Yes | Z31: 1 | AA31: yes
J32: Id2307 | K32: 1995 | L32: Oct | M32: 5 | N32: 0 | O32: 1033.74 | P32: tier - 3 | Q32: tier - 1 | R32: =IF('Hospitalisation Details'!I30="?","Unknown",'Hospitalisation Details'!I30) -> R1013 | T32: Id29 | U32: 35.86 | V32: 6.74 | W32: yes | X32: No | Y32: No | Z32: 2 | AA32: yes
J33: Id2306 | K33: 1994 | L33: Nov | M33: 17 | N33: 0 | O33: 1044 | P33: tier - 3 | Q33: tier - 2 | R33: =IF('Hospitalisation Details'!I31="?","Unknown",'Hospitalisation Details'!I31) -> R1013 | T33: Id30 | U33: 37.05 | V33: 8.44 | W33: No | X33: No | Y33: No | Z33: No major surgery | AA33: yes
J34: Id2305 | K34: 2002 | L34: Jul | M34: 20 | N34: 0 | O34: 1047 | P34: tier - 3 | Q34: tier - 1 | R34: =IF('Hospitalisation Details'!I32="?","Unknown",'Hospitalisation Details'!I32) -> R1013 | T34: Id31 | U34: 43.89 | V34: 8.71 | W34: No | X34: No | Y34: No | Z34: No major surgery | AA34: yes
J35: Id2304 | K35: 2002 | L35: Jul | M35: 1 | N35: 0 | O35: 1049 | P35: tier - 3 | Q35: tier - 2 | R35: =IF('Hospitalisation Details'!I33="?","Unknown",'Hospitalisation Details'!I33) -> R1012 | T35: Id32 | U35: 42.35 | V35: 5.08 | W35: yes | X35: No | Y35: No | Z35: No major surgery | AA35: yes
J36: Id2303 | K36: 1995 | L36: Jun | M36: 1 | N36: 0 | O36: 1056 | P36: tier - 3 | Q36: tier - 2 | R36: =IF('Hospitalisation Details'!I34="?","Unknown",'Hospitalisation Details'!I34) -> R1013 | T36: Id33 | U36: 31.35 | V36: 6.86 | W36: No | X36: No | Y36: No | Z36: No major surgery | AA36: yes
J37: Id2302 | K37: 1993 | L37: Sep | M37: 28 | N37: 0 | O37: 1068 | P37: tier - 3 | Q37: tier - 1 | R37: =IF('Hospitalisation Details'!I35="?","Unknown",'Hospitalisation Details'!I35) -> R1013 | T37: Id34 | U37: 47.6 | V37: 5.95 | W37: yes | X37: No | Y37: No | Z37: No major surgery | AA37: yes
J38: Id2301 | K38: 2004 | L38: Aug | M38: 24 | N38: 0 | O38: 1070 | P38: tier - 3 | Q38: tier - 3 | R38: =IF('Hospitalisation Details'!I36="?","Unknown",'Hospitalisation Details'!I36) -> R1013 | T38: Id35 | U38: 46.2 | V38: 6.09 | W38: No | X38: No | Y38: Yes | Z38: 1 | AA38: yes
J39: Id2300 | K39: 1997 | L39: Aug | M39: 13 | N39: 0 | O39: 1071 | P39: tier - 3 | Q39: tier - 3 | R39: =IF('Hospitalisation Details'!I37="?","Unknown",'Hospitalisation Details'!I37) -> R1013 | T39: Id36 | U39: 32.015 | V39: 11.75 | W39: No | X39: No | Y39: No | Z39: No major surgery | AA39: yes
J40: Id2299 | K40: 1998 | L40: Dec | M40: 26 | N40: 0 | O40: 1082 | P40: tier - 3 | Q40: tier - 2 | R40: =IF('Hospitalisation Details'!I38="?","Unknown",'Hospitalisation Details'!I38) -> R1013 | T40: Id37 | U40: 40.565 | V40: 7.37 | W40: No | X40: No | Y40: No | Z40: No major surgery | AA40: yes
...

Sheet Answer Data Transformation
A1: Sl No | B1: 1 | K1: 4 | M1: 5 | N1: 3 | Q1: 2 | R1: 3 | U1: 6 | V1: 7 | X1: 8
B3: Customer ID | C3: name | D3: Title | E3: First Name | F3: Last Name | I3: Customer ID | J3: BMI | K3: Weight Status | L3: HBA1C | M3: Diabetes Status | N3: Heart Issues | O3: Any Transplants | P3: Cancer history | Q3: NumberOfMajorSurgeries | R3: =PROPER('Answer Data Cleaning'!AA3) -> Smoker | T3: Customer ID | U3: Date of Birth | V3: Age | W3: children | X3: charges | Y3: Hospital tier | Z3: City tier | AA3: State ID
B4: Id1 | C4: Hawks, Ms. Kelly | D4: Ms | E4: Kelly | F4: Hawks | I4: Id1 | J4: 47.41 | K4: =IF(J4<18.5,"Underweight",IF(J4<25,"Normal Weight",IF(J4<30,"Overweight","Obesity"))) -> Obesity | L4: 7.47 | M4: =IF(L4<5.7,"Normal",IF(L4<6.5,"Prediabetes","Diabetes")) -> Diabetes | N4: =PROPER('Medical Examinations'!D2) -> No | O4: No | P4: No | Q4: 0 | R4: =PROPER('Answer Data Cleaning'!AA4) -> Yes | T4: Id2335 | U4: =TEXT(_xlfn.CONCAT('Answer Data Cleaning'!M4,"-",'Answer Data Cleaning'!L4,"-",'Answer Data Cleaning'!K4),"DD-MMM-YYYY") -> 09-Jul-1992 | V4: =DATEDIF(U4,"08-jun-2023","y") -> 30 | W4: 0 | X4: 563.84 | Y4: tier - 2 | Z4: tier - 3 | AA4: R1013
B5: Id2 | C5: Lehner, Mr. Matthew D | D5: Mr | E5: Matthew D | F5: Lehner | I5: Id2 | J5: 30.36 | K5: =IF(J5<18.5,"Underweight",IF(J5<25,"Normal Weight",IF(J5<30,"Overweight","Obesity"))) -> Obesity | L5: 5.77 | M5: =IF(L5<5.7,"Normal",IF(L5<6.5,"Prediabetes","Diabetes")) -> Prediabetes | N5: =PROPER('Medical Examinations'!D3) -> No | O5: No | P5: No | Q5: 0 | R5: =PROPER('Answer Data Cleaning'!AA5) -> Yes | T5: Id2334 | U5: =TEXT(_xlfn.CONCAT('Answer Data Cleaning'!M5,"-",'Answer Data Cleaning'!L5,"-",'Answer Data Cleaning'!K5),"DD-MMM-YYYY") -> 30-Nov-1992 | V5: =DATEDIF(U5,"08-jun-2023","y") -> 30 | W5: 0 | X5: 570.62 | Y5: tier - 2 | Z5: tier - 1 | AA5: R1013
B6: Id3 | C6: Lu, Mr. Phil | D6: Mr | E6: Phil | F6: Lu | I6: Id3 | J6: 34.485 | K6: =IF(J6<18.5,"Underweight",IF(J6<25,"Normal Weight",IF(J6<30,"Overweight","Obesity"))) -> Obesity | L6: 11.87 | M6: =IF(L6<5.7,"Normal",IF(L6<6.5,"Prediabetes","Diabetes")) -> Diabetes | N6: =PROPER('Medical Examinations'!D4) -> Yes | O6: No | P6: No | Q6: 2 | R6: =PROPER('Answer Data Cleaning'!AA6) -> Yes | T6: Id2333 | U6: =TEXT(_xlfn.CONCAT('Answer Data Cleaning'!M6,"-",'Answer Data Cleaning'!L6,"-",'Answer Data Cleaning'!K6),"DD-MMM-YYYY") -> 30-Jun-1993 | V6: =DATEDIF(U6,"08-jun-2023","y") -> 29 | W6: 0 | X6: 600 | Y6: tier - 2 | Z6: tier - 1 | AA6: R1013
B7: Id4 | C7: Osborne, Ms. Kelsey | D7: Ms | E7: Kelsey | F7: Osborne | I7: Id4 | J7: 38.095 | K7: =IF(J7<18.5,"Underweight",IF(J7<25,"Normal Weight",IF(J7<30,"Overweight","Obesity"))) -> Obesity | L7: 6.05 | M7: =IF(L7<5.7,"Normal",IF(L7<6.5,"Prediabetes","Diabetes")) -> Prediabetes | N7: =PROPER('Medical Examinations'!D5) -> No | O7: No | P7: No | Q7: 0 | R7: =PROPER('Answer Data Cleaning'!AA7) -> Yes | T7: Id2332 | U7: =TEXT(_xlfn.CONCAT('Answer Data Cleaning'!M7,"-",'Answer Data Cleaning'!L7,"-",'Answer Data Cleaning'!K7),"DD-MMM-YYYY") -> 13-Sep-1992 | V7: =DATEDIF(U7,"08-jun-2023","y") -> 30 | W7: 0 | X7: 604.54 | Y7: tier - 3 | Z7: tier - 3 | AA7: R1013
B8: Id5 | C8: Kadala, Ms. Kristyn | D8: Ms | E8: Kristyn | F8: Kadala | I8: Id5 | J8: 35.53 | K8: =IF(J8<18.5,"Underweight",IF(J8<25,"Normal Weight",IF(J8<30,"Overweight","Obesity"))) -> Obesity | L8: 5.45 | M8: =IF(L8<5.7,"Normal",IF(L8<6.5,"Prediabetes","Diabetes")) -> Normal | N8: =PROPER('Medical Examinations'!D6) -> No | O8: No | P8: No | Q8: 0 | R8: =PROPER('Answer Data Cleaning'!AA8) -> Yes | T8: Id2331 | U8: =TEXT(_xlfn.CONCAT('Answer Data Cleaning'!M8,"-",'Answer Data Cleaning'!L8,"-",'Answer Data Cleaning'!K8),"DD-MMM-YYYY") -> 27-Jul-1998 | V8: =DATEDIF(U8,"08-jun-2023","y") -> 24 | W8: 0 | X8: 637.26 | Y8: tier - 3 | Z8: tier - 3 | AA8: R1013
B9: Id6 | C9: Baker, Mr. Russell B. | D9: Mr | E9: Russell B | F9: Baker | I9: Id6 | J9: 32.8 | K9: =IF(J9<18.5,"Underweight",IF(J9<25,"Normal Weight",IF(J9<30,"Overweight","Obesity"))) -> Obesity | L9: 6.59 | M9: =IF(L9<5.7,"Normal",IF(L9<6.5,"Prediabetes","Diabetes")) -> Diabetes | N9: =PROPER('Medical Examinations'!D7) -> No | O9: No | P9: No | Q9: 0 | R9: =PROPER('Answer Data Cleaning'!AA9) -> Yes | T9: Id2330 | U9: =TEXT(_xlfn.CONCAT('Answer Data Cleaning'!M9,"-",'Answer Data Cleaning'!L9,"-",'Answer Data Cleaning'!K9),"DD-MMM-YYYY") -> 20-Nov-2001 | V9: =DATEDIF(U9,"08-jun-2023","y") -> 21 | W9: 0 | X9: 646.14 | Y9: tier - 3 | Z9: tier - 3 | AA9: R1012
B10: Id7 | C10: Macpherson, Mr. Scott | D10: Mr | E10: Scott | F10: Macpherson | I10: Id7 | J10: 36.4 | K10: =IF(J10<18.5,"Underweight",IF(J10<25,"Normal Weight",IF(J10<30,"Overweight","Obesity"))) -> Obesity | L10: 6.07 | M10: =IF(L10<5.7,"Normal",IF(L10<6.5,"Prediabetes","Diabetes")) -> Prediabetes | N10: =PROPER('Medical Examinations'!D8) -> No | O10: No | P10: No | Q10: 0 | R10: =PROPER('Answer Data Cleaning'!AA10) -> Yes | T10: Id2329 | U10: =TEXT(_xlfn.CONCAT('Answer Data Cleaning'!M10,"-",'Answer Data Cleaning'!L10,"-",'Answer Data Cleaning'!K10),"DD-MMM-YYYY") -> 01-Jun-1993 | V10: =DATEDIF(U10,"08-jun-2023","y") -> 30 | W10: 0 | X10: 650 | Y10: tier - 3 | Z10: tier - 3 | AA10: R1013
B11: Id8 | C11: Hallman, Mr. Stephen | D11: Mr | E11: Stephen | F11: Hallman | I11: Id8 | J11: 36.96 | K11: =IF(J11<18.5,"Underweight",IF(J11<25,"Normal Weight",IF(J11<30,"Overweight","Obesity"))) -> Obesity | L11: 7.93 | M11: =IF(L11<5.7,"Normal",IF(L11<6.5,"Prediabetes","Diabetes")) -> Diabetes | N11: =PROPER('Medical Examinations'!D9) -> No | O11: No | P11: No | Q11: 3 | R11: =PROPER('Answer Data Cleaning'!AA11) -> Yes | T11: Id2328 | U11: =TEXT(_xlfn.CONCAT('Answer Data Cleaning'!M11,"-",'Answer Data Cleaning'!L11,"-",'Answer Data Cleaning'!K11),"DD-MMM-YYYY") -> 04-Jul-1995 | V11: =DATEDIF(U11,"08-jun-2023","y") -> 27 | W11: 0 | X11: 650 | Y11: tier - 3 | Z11: tier - 3 | AA11: R1013
B12: Id9 | C12: Moran, Mr. Patrick R. | D12: Mr | E12: Patrick R | F12: Moran | I12: Id9 | J12: 41.14 | K12: =IF(J12<18.5,"Underweight",IF(J12<25,"Normal Weight",IF(J12<30,"Overweight","Obesity"))) -> Obesity | L12: 9.58 | M12: =IF(L12<5.7,"Normal",IF(L12<6.5,"Prediabetes","Diabetes")) -> Diabetes | N12: =PROPER('Medical Examinations'!D10) -> Yes | O12: No | P12: Yes | Q12: 1 | R12: =PROPER('Answer Data Cleaning'!AA12) -> Yes | T12: Id2327 | U12: =TEXT(_xlfn.CONCAT('Answer Data Cleaning'!M12,"-",'Answer Data Cleaning'!L12,"-",'Answer Data Cleaning'!K12),"DD-MMM-YYYY") -> 29-Nov-2002 | V12: =DATEDIF(U12,"08-jun-2023","y") -> 20 | W12: 0 | X12: 668 | Y12: tier - 3 | Z12: tier - 2 | AA12: R1012
B13: Id10 | C13: Benner, Ms. Brooke N. | D13: Ms | E13: Brooke N | F13: Benner | I13: Id10 | J13: 38.06 | K13: =IF(J13<18.5,"Underweight",IF(J13<25,"Normal Weight",IF(J13<30,"Overweight","Obesity"))) -> Obesity | L13: 10.79 | M13: =IF(L13<5.7,"Normal",IF(L13<6.5,"Prediabetes","Diabetes")) -> Diabetes | N13: =PROPER('Medical Examinations'!D11) -> No | O13: No | P13: No | Q13: 0 | R13: =PROPER('Answer Data Cleaning'!AA13) -> Yes | T13: Id2326 | U13: =TEXT(_xlfn.CONCAT('Answer Data Cleaning'!M13,"-",'Answer Data Cleaning'!L13,"-",'Answer Data Cleaning'!K13),"DD-MMM-YYYY") -> 09-Nov-1997 | V13: =DATEDIF(U13,"08-jun-2023","y") -> 25 | W13: 0 | X13: 670 | Y13: tier - 3 | Z13: tier - 3 | AA13: R1013
B14: Id11 | C14: Fierro Vargas, Ms. Paola Andrea | D14: Ms | E14: Paola Andrea | F14: Fierro Vargas | I14: Id11 | J14: 37.7 | K14: =IF(J14<18.5,"Underweight",IF(J14<25,"Normal Weight",IF(J14<30,"Overweight","Obesity"))) -> Obesity | L14: 5.96 | M14: =IF(L14<5.7,"Normal",IF(L14<6.5,"Prediabetes","Diabetes")) -> Prediabetes | N14: =PROPER('Medical Examinations'!D12) -> Yes | O14: No | P14: No | Q14: 2 | R14: =PROPER('Answer Data Cleaning'!AA14) -> Yes | T14: Id2325 | U14: =TEXT(_xlfn.CONCAT('Answer Data Cleaning'!M14,"-",'Answer Data Cleaning'!L14,"-",'Answer Data Cleaning'!K14),"DD-MMM-YYYY") -> 12-Sep-2001 | V14: =DATEDIF(U14,"08-jun-2023","y") -> 21 | W14: 0 | X14: 687.54 | Y14: tier - 3 | Z14: tier - 2 | AA14: R1013
B15: Id12 | C15: Franz, Mr. David | D15: Mr | E15: David | F15: Franz | I15: Id12 | J15: 42.13 | K15: =IF(J15<18.5,"Underweight",IF(J15<25,"Normal Weight",IF(J15<30,"Overweight","Obesity"))) -> Obesity | L15: 11.9 | M15: =IF(L15<5.7,"Normal",IF(L15<6.5,"Prediabetes","Diabetes")) -> Diabetes | N15: =PROPER('Medical Examinations'!D13) -> No | O15: No | P15: No | Q15: 0 | R15: =PROPER('Answer Data Cleaning'!AA15) -> Yes | T15: Id2324 | U15: =TEXT(_xlfn.CONCAT('Answer Data Cleaning'!M15,"-",'Answer Data Cleaning'!L15,"-",'Answer Data Cleaning'!K15),"DD-MMM-YYYY") -> 26-Dec-1999 | V15: =DATEDIF(U15,"08-jun-2023","y") -> 23 | W15: 0 | X15: 700 | Y15: tier - 2 | Z15: tier - 3 | AA15: R1013
... B74: Id71 | C74: Turner, Mr. Jeff | D74: Mr | E74: Jeff | F74: Turner | I74: Id71 | J74: 38.39 | K74: =IF(J74<18.5,"Underweight",IF(J74<25,"Normal Weight",IF(J74<30,"Overweight","Obesity"))) -> Obesity | L74: 4.25 | M74: =IF(L74<5.7,"Normal",IF(L74<6.5,"Prediabetes","Diabetes")) -> Normal | N74: =PROPER('Medical Examinations'!D72) -> No | O74: No | P74: No | Q74: 1 | R74: =PROPER('Answer Data Cleaning'!AA74) -> Yes | T74: Id2266 | U74: =TEXT(_xlfn.CONCAT('Answer Data Cleaning'!M74,"-",'Answer Data Cleaning'!L74,"-",'Answer Data Cleaning'!K74),"DD-MMM-YYYY") -> 01-Jul-2002 | V74: =DATEDIF(U74,"08-jun-2023","y") -> 20 | W74: 0 | X74: 1241 | Y74: tier - 2 | Z74: tier - 2 | AA74: R1013
B75: Id72 | C75: Rangel, Mr. Elenilton V. Sr. | D75: Mr | E75: Elenilton V | F75: Rangel | G75: Sr | I75: Id72 | J75: 32.3 | K75: =IF(J75<18.5,"Underweight",IF(J75<25,"Normal Weight",IF(J75<30,"Overweight","Obesity"))) -> Obesity | L75: 4.76 | M75: =IF(L75<5.7,"Normal",IF(L75<6.5,"Prediabetes","Diabetes")) -> Normal | N75: =PROPER('Medical Examinations'!D73) -> No | O75: No | P75: No | Q75: 2 | R75: =PROPER('Answer Data Cleaning'!AA75) -> Yes | T75: Id2265 | U75: =TEXT(_xlfn.CONCAT('Answer Data Cleaning'!M75,"-",'Answer Data Cleaning'!L75,"-",'Answer Data Cleaning'!K75),"DD-MMM-YYYY") -> 02-Aug-2003 | V75: =DATEDIF(U75,"08-jun-2023","y") -> 19 | W75: 0 | X75: 1241.57 | Y75: tier - 2 | Z75: tier - 2 | AA75: R1011
B76: Id73 | C76: Lacey, Ms. Maurya | D76: Ms | E76: Maurya | F76: Lacey | I76: Id73 | J76: 48.8 | K76: =IF(J76<18.5,"Underweight",IF(J76<25,"Normal Weight",IF(J76<30,"Overweight","Obesity"))) -> Obesity | L76: 6.22 | M76: =IF(L76<5.7,"Normal",IF(L76<6.5,"Prediabetes","Diabetes")) -> Prediabetes | N76: =PROPER('Medical Examinations'!D74) -> Yes | O76: No | P76: No | Q76: 2 | R76: =PROPER('Answer Data Cleaning'!AA76) -> Yes | T76: Id2264 | U76: =TEXT(_xlfn.CONCAT('Answer Data Cleaning'!M76,"-",'Answer Data Cleaning'!L76,"-",'Answer Data Cleaning'!K76),"DD-MMM-YYYY") -> 15-Sep-2003 | V76: =DATEDIF(U76,"08-jun-2023","y") -> 19 | W76: 0 | X76: 1242.26 | Y76: tier - 2 | Z76: tier - 1 | AA76: R1011
B77: Id74 | C77: Stiger, Ms. Samantha C | D77: Ms | E77: Samantha C | F77: Stiger | I77: Id74 | J77: 45.5 | K77: =IF(J77<18.5,"Underweight",IF(J77<25,"Normal Weight",IF(J77<30,"Overweight","Obesity"))) -> Obesity | L77: 7.96 | M77: =IF(L77<5.7,"Normal",IF(L77<6.5,"Prediabetes","Diabetes")) -> Diabetes | N77: =PROPER('Medical Examinations'!D75) -> No | O77: No | P77: No | Q77: 0 | R77: =PROPER('Answer Data Cleaning'!AA77) -> Yes | T77: Id2263 | U77: =TEXT(_xlfn.CONCAT('Answer Data Cleaning'!M77,"-",'Answer Data Cleaning'!L77,"-",'Answer Data Cleaning'!K77),"DD-MMM-YYYY") -> 08-Sep-2003 | V77: =DATEDIF(U77,"08-jun-2023","y") -> 19 | W77: 0 | X77: 1242.82 | Y77: tier - 2 | Z77: tier - 1 | AA77: R1011
B78: Id75 | C78: Caldwell, Ms. Bethany A | D78: Ms | E78: Bethany A | F78: Caldwell | I78: Id75 | J78: 53.61 | K78: =IF(J78<18.5,"Underweight",IF(J78<25,"Normal Weight",IF(J78<30,"Overweight","Obesity"))) -> Obesity | L78: 10.92 | M78: =IF(L78<5.7,"Normal",IF(L78<6.5,"Prediabetes","Diabetes")) -> Diabetes | N78: =PROPER('Medical Examinations'!D76) -> Yes | O78: No | P78: No | Q78: 1 | R78: =PROPER('Answer Data Cleaning'!AA78) -> Yes | T78: Id2262 | U78: =TEXT(_xlfn.CONCAT('Answer Data Cleaning'!M78,"-",'Answer Data Cleaning'!L78,"-",'Answer Data Cleaning'!K78),"DD-MMM-YYYY") -> 15-Sep-2003 | V78: =DATEDIF(U78,"08-jun-2023","y") -> 19 | W78: 0 | X78: 1252.41 | Y78: tier - 2 | Z78: tier - 3 | AA78: R1011
B79: Id76 | C79: Marmillod, Mr. Yves | D79: Mr | E79: Yves | F79: Marmillod | I79: Id76 | J79: 36.19 | K79: =IF(J79<18.5,"Underweight",IF(J79<25,"Normal Weight",IF(J79<30,"Overweight","Obesity"))) -> Obesity | L79: 11.51 | M79: =IF(L79<5.7,"Normal",IF(L79<6.5,"Prediabetes","Diabetes")) -> Diabetes | N79: =PROPER('Medical Examinations'!D77) -> Yes | O79: No | P79: No | Q79: 1 | R79: =PROPER('Answer Data Cleaning'!AA79) -> Yes | T79: Id2261 | U79: =TEXT(_xlfn.CONCAT('Answer Data Cleaning'!M79,"-",'Answer Data Cleaning'!L79,"-",'Answer Data Cleaning'!K79),"DD-MMM-YYYY") -> 04-Nov-1997 | V79: =DATEDIF(U79,"08-jun-2023","y") -> 25 | W79: 0 | X79: 1253 | Y79: tier - 2 | Z79: tier - 2 | AA79: R1013
B80: Id77 | C80: Cloutier-Simons, Ms. Danielle | D80: Ms | E80: Danielle | F80: Cloutier-Simons | I80: Id77 | J80: 34.6 | K80: =IF(J80<18.5,"Underweight",IF(J80<25,"Normal Weight",IF(J80<30,"Overweight","Obesity"))) -> Obesity | L80: 5.99 | M80: =IF(L80<5.7,"Normal",IF(L80<6.5,"Prediabetes","Diabetes")) -> Prediabetes | N80: =PROPER('Medical Examinations'!D78) -> Yes | O80: No | P80: No | Q80: 0 | R80: =PROPER('Answer Data Cleaning'!AA80) -> Yes | T80: Id2260 | U80: =TEXT(_xlfn.CONCAT('Answer Data Cleaning'!M80,"-",'Answer Data Cleaning'!L80,"-",'Answer Data Cleaning'!K80),"DD-MMM-YYYY") -> 10-Dec-2003 | V80: =DATEDIF(U80,"08-jun-2023","y") -> 19 | W80: 0 | X80: 1253.94 | Y80: tier - 2 | Z80: tier - 2 | AA80: R1011
B81: Id78 | C81: Vegas, Ms. Julia | D81: Ms | E81: Julia | F81: Vegas | I81: Id78 | J81: 54.12 | K81: =IF(J81<18.5,"Underweight",IF(J81<25,"Normal Weight",IF(J81<30,"Overweight","Obesity"))) -> Obesity | L81: 11.57 | M81: =IF(L81<5.7,"Normal",IF(L81<6.5,"Prediabetes","Diabetes")) -> Diabetes | N81: =PROPER('Medical Examinations'!D79) -> No | O81: No | P81: No | Q81: 0 | R81: =PROPER('Answer Data Cleaning'!AA81) -> Yes | T81: Id2259 | U81: =TEXT(_xlfn.CONCAT('Answer Data Cleaning'!M81,"-",'Answer Data Cleaning'!L81,"-",'Answer Data Cleaning'!K81),"DD-MMM-YYYY") -> 13-Oct-2003 | V81: =DATEDIF(U81,"08-jun-2023","y") -> 19 | W81: 0 | X81: 1256.3 | Y81: tier - 2 | Z81: tier - 3 | AA81: R1011
B82: Id79 | C82: Cochran, Mr. Joshua | D82: Mr | E82: Joshua | F82: Cochran | I82: Id79 | J82: 48.82 | K82: =IF(J82<18.5,"Underweight",IF(J82<25,"Normal Weight",IF(J82<30,"Overweight","Obesity"))) -> Obesity | L82: 6.67 | M82: =IF(L82<5.7,"Normal",IF(L82<6.5,"Prediabetes","Diabetes")) -> Diabetes | N82: =PROPER('Medical Examinations'!D80) -> Yes | O82: No | P82: No | Q82: 0 | R82: =PROPER('Answer Data Cleaning'!AA82) -> Yes | T82: Id2258 | U82: =TEXT(_xlfn.CONCAT('Answer Data Cleaning'!M82,"-",'Answer Data Cleaning'!L82,"-",'Answer Data Cleaning'!K82),"DD-MMM-YYYY") -> 30-Oct-2003 | V82: =DATEDIF(U82,"08-jun-2023","y") -> 19 | W82: 0 | X82: 1261.44 | Y82: tier - 2 | Z82: tier - 3 | AA82: R1011
B83: Id80 | C83: Holtzapple, Ms. Jennifer | D83: Ms | E83: Jennifer | F83: Holtzapple | I83: Id80 | J83: 51.01 | K83: =IF(J83<18.5,"Underweight",IF(J83<25,"Normal Weight",IF(J83<30,"Overweight","Obesity"))) -> Obesity | L83: 9.2 | M83: =IF(L83<5.7,"Normal",IF(L83<6.5,"Prediabetes","Diabetes")) -> Diabetes | N83: =PROPER('Medical Examinations'!D81) -> No | O83: No | P83: No | Q83: 0 | R83: =PROPER('Answer Data Cleaning'!AA83) -> Yes | T83: Id2257 | U83: =TEXT(_xlfn.CONCAT('Answer Data Cleaning'!M83,"-",'Answer Data Cleaning'!L83,"-",'Answer Data Cleaning'!K83),"DD-MMM-YYYY") -> 15-Aug-2003 | V83: =DATEDIF(U83,"08-jun-2023","y") -> 19 | W83: 0 | X83: 1261.86 | Y83: tier - 2 | Z83: tier - 3 | AA83: R1011
B84: Id81 | C84: Meyer, Ms. Gwen M. | D84: Ms | E84: Gwen M | F84: Meyer | I84: Id81 | J84: 45.65 | K84: =IF(J84<18.5,"Underweight",IF(J84<25,"Normal Weight",IF(J84<30,"Overweight","Obesity"))) -> Obesity | L84: 5.11 | M84: =IF(L84<5.7,"Normal",IF(L84<6.5,"Prediabetes","Diabetes")) -> Normal | N84: =PROPER('Medical Examinations'!D82) -> Yes | O84: No | P84: No | Q84: 1 | R84: =PROPER('Answer Data Cleaning'!AA84) -> Yes | T84: Id2256 | U84: =TEXT(_xlfn.CONCAT('Answer Data Cleaning'!M84,"-",'Answer Data Cleaning'!L84,"-",'Answer Data Cleaning'!K84),"DD-MMM-YYYY") -> 21-Nov-2003 | V84: =DATEDIF(U84,"08-jun-2023","y") -> 19 | W84: 0 | X84: 1263.25 | Y84: tier - 2 | Z84: tier - 3 | AA84: R1011
B85: Id82 | C85: Brickley, Mr. Patrick | D85: Mr | E85: Patrick | F85: Brickley | I85: Id82 | J85: 52.9 | K85: =IF(J85<18.5,"Underweight",IF(J85<25,"Normal Weight",IF(J85<30,"Overweight","Obesity"))) -> Obesity | L85: 5.34 | M85: =IF(L85<5.7,"Normal",IF(L85<6.5,"Prediabetes","Diabetes")) -> Normal | N85: =PROPER('Medical Examinations'!D83) -> No | O85: No | P85: No | Q85: 0 | R85: =PROPER('Answer Data Cleaning'!AA85) -> Yes | T85: Id2255 | U85: =TEXT(_xlfn.CONCAT('Answer Data Cleaning'!M85,"-",'Answer Data Cleaning'!L85,"-",'Answer Data Cleaning'!K85),"DD-MMM-YYYY") -> 04-Dec-2002 | V85: =DATEDIF(U85,"08-jun-2023","y") -> 20 | W85: 0 | X85: 1267 | Y85: tier - 2 | Z85: tier - 1 | AA85: R1013
B86: Id83 | C86: Magee, Ms. Kate | D86: Ms | E86: Kate | F86: Magee | I86: Id83 | J86: 45.41 | K86: =IF(J86<18.5,"Underweight",IF(J86<25,"Normal Weight",IF(J86<30,"Overweight","Obesity"))) -> Obesity | L86: 4.03 | M86: =IF(L86<5.7,"Normal",IF(L86<6.5,"Prediabetes","Diabetes")) -> Normal | N86: =PROPER('Medical Examinations'!D84) -> Yes | O86: No | P86: No | Q86: 1 | R86: =PROPER('Answer Data Cleaning'!AA86) -> Yes | T86: Id2254 | U86: =TEXT(_xlfn.CONCAT('Answer Data Cleaning'!M86,"-",'Answer Data Cleaning'!L86,"-",'Answer Data Cleaning'!K86),"DD-MMM-YYYY") -> 26-Oct-1997 | V86: =DATEDIF(U86,"08-jun-2023","y") -> 25 | W86: 0 | X86: 1276 | Y86: tier - 2 | Z86: tier - 2 | AA86: R1012
B87: Id84 | C87: Thoma, Mr. Kevin | D87: Mr | E87: Kevin | F87: Thoma | I87: Id84 | J87: 49.41 | K87: =IF(J87<18.5,"Underweight",IF(J87<25,"Normal Weight",IF(J87<30,"Overweight","Obesity"))) -> Obesity | L87: 4.23 | M87: =IF(L87<5.7,"Normal",IF(L87<6.5,"Prediabetes","Diabetes")) -> Normal | N87: =PROPER('Medical Examinations'!D85) -> Yes | O87: No | P87: Yes | Q87: 1 | R87: =PROPER('Answer Data Cleaning'!AA87) -> Yes | T87: Id2253 | U87: =TEXT(_xlfn.CONCAT('Answer Data Cleaning'!M87,"-",'Answer Data Cleaning'!L87,"-",'Answer Data Cleaning'!K87),"DD-MMM-YYYY") -> 30-Sep-2004 | V87: =DATEDIF(U87,"08-jun-2023","y") -> 18 | W87: 0 | X87: 1283 | Y87: tier - 2 | Z87: tier - 1 | AA87: R1013
... B190: Id187 | C190: Dublin, Mr. Andrew P | D190: Mr | E190: Andrew P | F190: Dublin | I190: Id187 | J190: 53.21 | K190: =IF(J190<18.5,"Underweight",IF(J190<25,"Normal Weight",IF(J190<30,"Overweight","Obesity"))) -> Obesity | L190: 4.27 | M190: =IF(L190<5.7,"Normal",IF(L190<6.5,"Prediabetes","Diabetes")) -> Normal | N190: =PROPER('Medical Examinations'!D188) -> No | O190: No | P190: No | Q190: 1 | R190: =PROPER('Answer Data Cleaning'!AA190) -> Yes | T190: Id2150 | U190: =TEXT(_xlfn.CONCAT('Answer Data Cleaning'!M190,"-",'Answer Data Cleaning'!L190,"-",'Answer Data Cleaning'!K190),"DD-MMM-YYYY") -> 05-Oct-1998 | V190: =DATEDIF(U190,"08-jun-2023","y") -> 24 | W190: 0 | X190: 1972.95 | Y190: tier - 3 | Z190: tier - 1 | AA190: R1011
B191: Id188 | C191: Cleland, Mr. George M. V | D191: Mr | E191: George M | F191: Cleland | G191: V | I191: Id188 | J191: 38.73 | K191: =IF(J191<18.5,"Underweight",IF(J191<25,"Normal Weight",IF(J191<30,"Overweight","Obesity"))) -> Obesity | L191: 11.51 | M191: =IF(L191<5.7,"Normal",IF(L191<6.5,"Prediabetes","Diabetes")) -> Diabetes | N191: =PROPER('Medical Examinations'!D189) -> No | O191: No | P191: No | Q191: 2 | R191: =PROPER('Answer Data Cleaning'!AA191) -> Yes | T191: Id2149 | U191: =TEXT(_xlfn.CONCAT('Answer Data Cleaning'!M191,"-",'Answer Data Cleaning'!L191,"-",'Answer Data Cleaning'!K191),"DD-MMM-YYYY") -> 29-Sep-1998 | V191: =DATEDIF(U191,"08-jun-2023","y") -> 24 | W191: 0 | X191: 1977.82 | Y191: tier - 3 | Z191: tier - 1 | AA191: R1011
B192: Id189 | C192: Evans, Ms. Sarah | D192: Ms | E192: Sarah | F192: Evans | I192: Id189 | J192: 29.73 | K192: =IF(J192<18.5,"Underweight",IF(J192<25,"Normal Weight",IF(J192<30,"Overweight","Obesity"))) -> Overweight | L192: 7.22 | M192: =IF(L192<5.7,"Normal",IF(L192<6.5,"Prediabetes","Diabetes")) -> Diabetes | N192: =PROPER('Medical Examinations'!D190) -> No | O192: No | P192: No | Q192: 0 | R192: =PROPER('Answer Data Cleaning'!AA192) -> Yes | T192: Id2148 | U192: =TEXT(_xlfn.CONCAT('Answer Data Cleaning'!M192,"-",'Answer Data Cleaning'!L192,"-",'Answer Data Cleaning'!K192),"DD-MMM-YYYY") -> 16-Jul-2002 | V192: =DATEDIF(U192,"08-jun-2023","y") -> 20 | W192: 1 | X192: 1980.07 | Y192: tier - 3 | Z192: tier - 3 | AA192: R1011
B193: Id190 | C193: Boyd, Ms. Lara | D193: Ms | E193: Lara | F193: Boyd | I193: Id190 | J193: 34.7 | K193: =IF(J193<18.5,"Underweight",IF(J193<25,"Normal Weight",IF(J193<30,"Overweight","Obesity"))) -> Obesity | L193: 4.37 | M193: =IF(L193<5.7,"Normal",IF(L193<6.5,"Prediabetes","Diabetes")) -> Normal | N193: =PROPER('Medical Examinations'!D191) -> No | O193: No | P193: Yes | Q193: 1 | R193: =PROPER('Answer Data Cleaning'!AA193) -> Yes | T193: Id2147 | U193: =TEXT(_xlfn.CONCAT('Answer Data Cleaning'!M193,"-",'Answer Data Cleaning'!L193,"-",'Answer Data Cleaning'!K193),"DD-MMM-YYYY") -> 29-Dec-1998 | V193: =DATEDIF(U193,"08-jun-2023","y") -> 24 | W193: 0 | X193: 1981.58 | Y193: tier - 3 | Z193: tier - 1 | AA193: R1013
B194: Id191 | C194: Roulier, Mr. Sebastien | D194: Mr | E194: Sebastien | F194: Roulier | I194: Id191 | J194: 38.28 | K194: =IF(J194<18.5,"Underweight",IF(J194<25,"Normal Weight",IF(J194<30,"Overweight","Obesity"))) -> Obesity | L194: 11.56 | M194: =IF(L194<5.7,"Normal",IF(L194<6.5,"Prediabetes","Diabetes")) -> Diabetes | N194: =PROPER('Medical Examinations'!D192) -> Yes | O194: No | P194: No | Q194: 1 | R194: =PROPER('Answer Data Cleaning'!AA194) -> Yes | T194: Id2146 | U194: =TEXT(_xlfn.CONCAT('Answer Data Cleaning'!M194,"-",'Answer Data Cleaning'!L194,"-",'Answer Data Cleaning'!K194),"DD-MMM-YYYY") -> 29-Sep-2002 | V194: =DATEDIF(U194,"08-jun-2023","y") -> 20 | W194: 0 | X194: 1984.45 | Y194: tier - 3 | Z194: tier - 3 | AA194: R1016
B195: Id192 | C195: Mullins, Mr. Padraig | D195: Mr | E195: Padraig | F195: Mullins | I195: Id192 | J195: 33.57 | K195: =IF(J195<18.5,"Underweight",IF(J195<25,"Normal Weight",IF(J195<30,"Overweight","Obesity"))) -> Obesity | L195: 8.82 | M195: =IF(L195<5.7,"Normal",IF(L195<6.5,"Prediabetes","Diabetes")) -> Diabetes | N195: =PROPER('Medical Examinations'!D193) -> Yes | O195: No | P195: No | Q195: 0 | R195: =PROPER('Answer Data Cleaning'!AA195) -> Yes | T195: Id2145 | U195: =TEXT(_xlfn.CONCAT('Answer Data Cleaning'!M195,"-",'Answer Data Cleaning'!L195,"-",'Answer Data Cleaning'!K195),"DD-MMM-YYYY") -> 14-Sep-1998 | V195: =DATEDIF(U195,"08-jun-2023","y") -> 24 | W195: 0 | X195: 1986.93 | Y195: tier - 3 | Z195: tier - 2 | AA195: R1013
B196: Id193 | C196: Hofmann, Ms. Heather | D196: Ms | E196: Heather | F196: Hofmann | I196: Id193 | J196: 52.06 | K196: =IF(J196<18.5,"Underweight",IF(J196<25,"Normal Weight",IF(J196<30,"Overweight","Obesity"))) -> Obesity | L196: 4.69 | M196: =IF(L196<5.7,"Normal",IF(L196<6.5,"Prediabetes","Diabetes")) -> Normal | N196: =PROPER('Medical Examinations'!D194) -> No | O196: No | P196: No | Q196: 1 | R196: =PROPER('Answer Data Cleaning'!AA196) -> Yes | T196: Id2144 | U196: =TEXT(_xlfn.CONCAT('Answer Data Cleaning'!M196,"-",'Answer Data Cleaning'!L196,"-",'Answer Data Cleaning'!K196),"DD-MMM-YYYY") -> 14-Aug-2001 | V196: =DATEDIF(U196,"08-jun-2023","y") -> 21 | W196: 0 | X196: 2007.95 | Y196: tier - 3 | Z196: tier - 2 | AA196: R1011
B197: Id194 | C197: Garcia Garcia, Mr. Jorge | D197: Mr | E197: Jorge | F197: Garcia Garcia | I197: Id194 | J197: 38.17 | K197: =IF(J197<18.5,"Underweight",IF(J197<25,"Normal Weight",IF(J197<30,"Overweight","Obesity"))) -> Obesity | L197: 4.53 | M197: =IF(L197<5.7,"Normal",IF(L197<6.5,"Prediabetes","Diabetes")) -> Normal | N197: =PROPER('Medical Examinations'!D195) -> No | O197: yes | P197: No | Q197: 1 | R197: =PROPER('Answer Data Cleaning'!AA197) -> Yes | T197: Id2143 | U197: =TEXT(_xlfn.CONCAT('Answer Data Cleaning'!M197,"-",'Answer Data Cleaning'!L197,"-",'Answer Data Cleaning'!K197),"DD-MMM-YYYY") -> 01-Jul-2001 | V197: =DATEDIF(U197,"08-jun-2023","y") -> 21 | W197: 0 | X197: 2020.18 | Y197: tier - 3 | Z197: tier - 1 | AA197: R1011
B198: Id195 | C198: Klecker, Mr. Jack R | D198: Mr | E198: Jack R | F198: Klecker | I198: Id195 | J198: 36.955 | K198: =IF(J198<18.5,"Underweight",IF(J198<25,"Normal Weight",IF(J198<30,"Overweight","Obesity"))) -> Obesity | L198: 5.84 | M198: =IF(L198<5.7,"Normal",IF(L198<6.5,"Prediabetes","Diabetes")) -> Prediabetes | N198: =PROPER('Medical Examinations'!D196) -> No | O198: No | P198: Yes | Q198: 1 | R198: =PROPER('Answer Data Cleaning'!AA198) -> Yes | T198: Id2142 | U198: =TEXT(_xlfn.CONCAT('Answer Data Cleaning'!M198,"-",'Answer Data Cleaning'!L198,"-",'Answer Data Cleaning'!K198),"DD-MMM-YYYY") -> 06-Sep-2001 | V198: =DATEDIF(U198,"08-jun-2023","y") -> 21 | W198: 0 | X198: 2020.55 | Y198: tier - 3 | Z198: tier - 2 | AA198: R1013
B199: Id196 | C199: Cancre, Mr. Felix | D199: Mr | E199: Felix | F199: Cancre | I199: Id196 | J199: 34.4 | K199: =IF(J199<18.5,"Underweight",IF(J199<25,"Normal Weight",IF(J199<30,"Overweight","Obesity"))) -> Obesity | L199: 4.9 | M199: =IF(L199<5.7,"Normal",IF(L199<6.5,"Prediabetes","Diabetes")) -> Normal | N199: =PROPER('Medical Examinations'!D197) -> No | O199: No | P199: Yes | Q199: 1 | R199: =PROPER('Answer Data Cleaning'!AA199) -> Yes | T199: Id2141 | U199: =TEXT(_xlfn.CONCAT('Answer Data Cleaning'!M199,"-",'Answer Data Cleaning'!L199,"-",'Answer Data Cleaning'!K199),"DD-MMM-YYYY") -> 04-Aug-2001 | V199: =DATEDIF(U199,"08-jun-2023","y") -> 21 | W199: 0 | X199: 2026.97 | Y199: tier - 3 | Z199: tier - 2 | AA199: R1013
B200: Id197 | C200: Denucci, Mr. Christopher C | D200: Mr | E200: Christopher C | F200: Denucci | I200: Id197 | J200: 31.73 | K200: =IF(J200<18.5,"Underweight",IF(J200<25,"Normal Weight",IF(J200<30,"Overweight","Obesity"))) -> Obesity | L200: 4.3 | M200: =IF(L200<5.7,"Normal",IF(L200<6.5,"Prediabetes","Diabetes")) -> Normal | N200: =PROPER('Medical Examinations'!D198) -> No | O200: No | P200: No | Q200: 0 | R200: =PROPER('Answer Data Cleaning'!AA200) -> Yes | T200: Id2140 | U200: =TEXT(_xlfn.CONCAT('Answer Data Cleaning'!M200,"-",'Answer Data Cleaning'!L200,"-",'Answer Data Cleaning'!K200),"DD-MMM-YYYY") -> 02-Sep-2000 | V200: =DATEDIF(U200,"08-jun-2023","y") -> 22 | W200: 0 | X200: 2045.69 | Y200: tier - 3 | Z200: tier - 3 | AA200: R1012
B201: Id198 | C201: Saldana, Mr. Jesse | D201: Mr | E201: Jesse | F201: Saldana | I201: Id198 | J201: 36.64 | K201: =IF(J201<18.5,"Underweight",IF(J201<25,"Normal Weight",IF(J201<30,"Overweight","Obesity"))) -> Obesity | L201: 11.34 | M201: =IF(L201<5.7,"Normal",IF(L201<6.5,"Prediabetes","Diabetes")) -> Diabetes | N201: =PROPER('Medical Examinations'!D199) -> No | O201: No | P201: No | Q201: 0 | R201: =PROPER('Answer Data Cleaning'!AA201) -> Yes | T201: Id2139 | U201: =TEXT(_xlfn.CONCAT('Answer Data Cleaning'!M201,"-",'Answer Data Cleaning'!L201,"-",'Answer Data Cleaning'!K201),"DD-MMM-YYYY") -> 26-Jul-2000 | V201: =DATEDIF(U201,"08-jun-2023","y") -> 22 | W201: 0 | X201: 2055.32 | Y201: tier - 3 | Z201: tier - 3 | AA201: R1012
...

Sheet Healthcare
A1: 1,2 | B1: Customer ID | C1: =VLOOKUP($B1,'Answer Data Transformation'!$B$3:$F$2338,4,FALSE) -> First Name | D1: =VLOOKUP($B1,'Answer Data Transformation'!$I$3:$R$2338,2,FALSE) -> BMI | E1: =VLOOKUP($B1,'Answer Data Transformation'!$I$3:$R$2338,4,FALSE) -> HBA1C | F1: =VLOOKUP($B1,'Answer Data Transformation'!$I$3:$R$2338,6,FALSE) -> Heart Issues | G1: =VLOOKUP($B1,'Answer Data Transformation'!$I$3:$R$2338,7,FALSE) -> Any Transplants | H1: =VLOOKUP($B1,'Answer Data Transformation'!$I$3:$R$2338,8,FALSE) -> Cancer history | I1: =VLOOKUP($B1,'Answer Data Transformation'!$I$3:$R$2338,9,FALSE) -> NumberOfMajorSurgeries | J1: =VLOOKUP($B1,'Answer Data Transformation'!$I$3:$R$2338,10,FALSE) -> Smoker | K1: =VLOOKUP($B1,'Answer Data Transformation'!$I$3:$R$2338,3,FALSE) -> Weight Status | L1: =VLOOKUP($B1,'Answer Data Transformation'!$I$3:$R$2338,5,FALSE) -> Diabetes Status | M1: =VLOOKUP($B1,'Answer Data Transformation'!$T$3:$AA$2346,2,FALSE) -> Date of Birth | N1: =VLOOKUP($B1,'Answer Data Transformation'!$T$3:$AA$2346,4,FALSE) -> children | O1: =VLOOKUP($B1,'Answer Data Transformation'!$T$3:$AA$2346,5,FALSE) -> charges | P1: =VLOOKUP($B1,'Answer Data Transformation'!$T$3:$AA$2346,6,FALSE) -> Hospital tier | Q1: =VLOOKUP($B1,'Answer Data Transformation'!$T$3:$AA$2346,7,FALSE) -> City tier | R1: =VLOOKUP($B1,'Answer Data Transformation'!$T$3:$AA$2346,8,FALSE) -> State ID | S1: =VLOOKUP($B1,'Answer Data Transformation'!$T$3:$AA$2346,3,FALSE) -> Age
B2: Id1 | C2: =VLOOKUP(B2,'Answer Data Transformation'!$B$3:$F$2338,4,FALSE) -> Kelly | D2: =VLOOKUP($B2,'Answer Data Transformation'!$I$3:$R$2338,2,FALSE) -> 47.41 | E2: =VLOOKUP($B2,'Answer Data Transformation'!$I$3:$R$2338,4,FALSE) -> 7.47 | F2: =VLOOKUP($B2,'Answer Data Transformation'!$I$3:$R$2338,6,FALSE) -> No | G2: =VLOOKUP($B2,'Answer Data Transformation'!$I$3:$R$2338,7,FALSE) -> No | H2: =VLOOKUP($B2,'Answer Data Transformation'!$I$3:$R$2338,8,FALSE) -> No | I2: =VLOOKUP($B2,'Answer Data Transformation'!$I$3:$R$2338,9,FALSE) -> 0 | J2: =VLOOKUP($B2,'Answer Data Transformation'!$I$3:$R$2338,10,FALSE) -> Yes | K2: =VLOOKUP($B2,'Answer Data Transformation'!$I$3:$R$2338,3,FALSE) -> Obesity | L2: =VLOOKUP($B2,'Answer Data Transformation'!$I$3:$R$2338,5,FALSE) -> Diabetes | M2: =VLOOKUP($B2,'Answer Data Transformation'!$T$3:$AA$2346,2,FALSE) -> 12-Oct-1968 | N2: =VLOOKUP($B2,'Answer Data Transformation'!$T$3:$AA$2346,4,FALSE) -> 0 | O2: =VLOOKUP($B2,'Answer Data Transformation'!$T$3:$AA$2346,5,FALSE) -> 63770.43 | P2: =VLOOKUP($B2,'Answer Data Transformation'!$T$3:$AA$2346,6,FALSE) -> tier - 1 | Q2: =VLOOKUP($B2,'Answer Data Transformation'!$T$3:$AA$2346,7,FALSE) -> tier - 3 | R2: =VLOOKUP($B2,'Answer Data Transformation'!$T$3:$AA$2346,8,FALSE) -> R1013 | S2: =VLOOKUP($B2,'Answer Data Transformation'!$T$3:$AA$2346,3,FALSE) -> 54
B3: Id2 | C3: =VLOOKUP(B3,'Answer Data Transformation'!$B$3:$F$2338,4,FALSE) -> Matthew D | D3: =VLOOKUP($B3,'Answer Data Transformation'!$I$3:$R$2338,2,FALSE) -> 30.36 | E3: =VLOOKUP($B3,'Answer Data Transformation'!$I$3:$R$2338,4,FALSE) -> 5.77 | F3: =VLOOKUP($B3,'Answer Data Transformation'!$I$3:$R$2338,6,FALSE) -> No | G3: =VLOOKUP($B3,'Answer Data Transformation'!$I$3:$R$2338,7,FALSE) -> No | H3: =VLOOKUP($B3,'Answer Data Transformation'!$I$3:$R$2338,8,FALSE) -> No | I3: =VLOOKUP($B3,'Answer Data Transformation'!$I$3:$R$2338,9,FALSE) -> 0 | J3: =VLOOKUP($B3,'Answer Data Transformation'!$I$3:$R$2338,10,FALSE) -> Yes | K3: =VLOOKUP($B3,'Answer Data Transformation'!$I$3:$R$2338,3,FALSE) -> Obesity | L3: =VLOOKUP($B3,'Answer Data Transformation'!$I$3:$R$2338,5,FALSE) -> Prediabetes | M3: =VLOOKUP($B3,'Answer Data Transformation'!$T$3:$AA$2346,2,FALSE) -> 08-Jun-1977 | N3: =VLOOKUP($B3,'Answer Data Transformation'!$T$3:$AA$2346,4,FALSE) -> 0 | O3: =VLOOKUP($B3,'Answer Data Transformation'!$T$3:$AA$2346,5,FALSE) -> 62592.87 | P3: =VLOOKUP($B3,'Answer Data Transformation'!$T$3:$AA$2346,6,FALSE) -> tier - 2 | Q3: =VLOOKUP($B3,'Answer Data Transformation'!$T$3:$AA$2346,7,FALSE) -> tier - 3 | R3: =VLOOKUP($B3,'Answer Data Transformation'!$T$3:$AA$2346,8,FALSE) -> R1013 | S3: =VLOOKUP($B3,'Answer Data Transformation'!$T$3:$AA$2346,3,FALSE) -> 46
B4: Id3 | C4: =VLOOKUP(B4,'Answer Data Transformation'!$B$3:$F$2338,4,FALSE) -> Phil | D4: =VLOOKUP($B4,'Answer Data Transformation'!$I$3:$R$2338,2,FALSE) -> 34.485 | E4: =VLOOKUP($B4,'Answer Data Transformation'!$I$3:$R$2338,4,FALSE) -> 11.87 | F4: =VLOOKUP($B4,'Answer Data Transformation'!$I$3:$R$2338,6,FALSE) -> Yes | G4: =VLOOKUP($B4,'Answer Data Transformation'!$I$3:$R$2338,7,FALSE) -> No | H4: =VLOOKUP($B4,'Answer Data Transformation'!$I$3:$R$2338,8,FALSE) -> No | I4: =VLOOKUP($B4,'Answer Data Transformation'!$I$3:$R$2338,9,FALSE) -> 2 | J4: =VLOOKUP($B4,'Answer Data Transformation'!$I$3:$R$2338,10,FALSE) -> Yes | K4: =VLOOKUP($B4,'Answer Data Transformation'!$I$3:$R$2338,3,FALSE) -> Obesity | L4: =VLOOKUP($B4,'Answer Data Transformation'!$I$3:$R$2338,5,FALSE) -> Diabetes | M4: =VLOOKUP($B4,'Answer Data Transformation'!$T$3:$AA$2346,2,FALSE) -> 11-Sep-1970 | N4: =VLOOKUP($B4,'Answer Data Transformation'!$T$3:$AA$2346,4,FALSE) -> 3 | O4: =VLOOKUP($B4,'Answer Data Transformation'!$T$3:$AA$2346,5,FALSE) -> 60021.4 | P4: =VLOOKUP($B4,'Answer Data Transformation'!$T$3:$AA$2346,6,FALSE) -> tier - 1 | Q4: =VLOOKUP($B4,'Answer Data Transformation'!$T$3:$AA$2346,7,FALSE) -> tier - 1 | R4: =VLOOKUP($B4,'Answer Data Transformation'!$T$3:$AA$2346,8,FALSE) -> R1012 | S4: =VLOOKUP($B4,'Answer Data Transformation'!$T$3:$AA$2346,3,FALSE) -> 52
B5: Id4 | C5: =VLOOKUP(B5,'Answer Data Transformation'!$B$3:$F$2338,4,FALSE) -> Kelsey | D5: =VLOOKUP($B5,'Answer Data Transformation'!$I$3:$R$2338,2,FALSE) -> 38.095 | E5: =VLOOKUP($B5,'Answer Data Transformation'!$I$3:$R$2338,4,FALSE) -> 6.05 | F5: =VLOOKUP($B5,'Answer Data Transformation'!$I$3:$R$2338,6,FALSE) -> No | G5: =VLOOKUP($B5,'Answer Data Transformation'!$I$3:$R$2338,7,FALSE) -> No | H5: =VLOOKUP($B5,'Answer Data Transformation'!$I$3:$R$2338,8,FALSE) -> No | I5: =VLOOKUP($B5,'Answer Data Transformation'!$I$3:$R$2338,9,FALSE) -> 0 | J5: =VLOOKUP($B5,'Answer Data Transformation'!$I$3:$R$2338,10,FALSE) -> Yes | K5: =VLOOKUP($B5,'Answer Data Transformation'!$I$3:$R$2338,3,FALSE) -> Obesity | L5: =VLOOKUP($B5,'Answer Data Transformation'!$I$3:$R$2338,5,FALSE) -> Prediabetes | M5: =VLOOKUP($B5,'Answer Data Transformation'!$T$3:$AA$2346,2,FALSE) -> 06-Jun-1991 | N5: =VLOOKUP($B5,'Answer Data Transformation'!$T$3:$AA$2346,4,FALSE) -> 1 | O5: =VLOOKUP($B5,'Answer Data Transformation'!$T$3:$AA$2346,5,FALSE) -> 58571.07 | P5: =VLOOKUP($B5,'Answer Data Transformation'!$T$3:$AA$2346,6,FALSE) -> tier - 1 | Q5: =VLOOKUP($B5,'Answer Data Transformation'!$T$3:$AA$2346,7,FALSE) -> tier - 3 | R5: =VLOOKUP($B5,'Answer Data Transformation'!$T$3:$AA$2346,8,FALSE) -> R1024 | S5: =VLOOKUP($B5,'Answer Data Transformation'!$T$3:$AA$2346,3,FALSE) -> 32
B6: Id5 | C6: =VLOOKUP(B6,'Answer Data Transformation'!$B$3:$F$2338,4,FALSE) -> Kristyn | D6: =VLOOKUP($B6,'Answer Data Transformation'!$I$3:$R$2338,2,FALSE) -> 35.53 | E6: =VLOOKUP($B6,'Answer Data Transformation'!$I$3:$R$2338,4,FALSE) -> 5.45 | F6: =VLOOKUP($B6,'Answer Data Transformation'!$I$3:$R$2338,6,FALSE) -> No | G6: =VLOOKUP($B6,'Answer Data Transformation'!$I$3:$R$2338,7,FALSE) -> No | H6: =VLOOKUP($B6,'Answer Data Transformation'!$I$3:$R$2338,8,FALSE) -> No | I6: =VLOOKUP($B6,'Answer Data Transformation'!$I$3:$R$2338,9,FALSE) -> 0 | J6: =VLOOKUP($B6,'Answer Data Transformation'!$I$3:$R$2338,10,FALSE) -> Yes | K6: =VLOOKUP($B6,'Answer Data Transformation'!$I$3:$R$2338,3,FALSE) -> Obesity | L6: =VLOOKUP($B6,'Answer Data Transformation'!$I$3:$R$2338,5,FALSE) -> Normal | M6: =VLOOKUP($B6,'Answer Data Transformation'!$T$3:$AA$2346,2,FALSE) -> 19-Jun-1989 | N6: =VLOOKUP($B6,'Answer Data Transformation'!$T$3:$AA$2346,4,FALSE) -> 0 | O6: =VLOOKUP($B6,'Answer Data Transformation'!$T$3:$AA$2346,5,FALSE) -> 55135.4 | P6: =VLOOKUP($B6,'Answer Data Transformation'!$T$3:$AA$2346,6,FALSE) -> tier - 1 | Q6: =VLOOKUP($B6,'Answer Data Transformation'!$T$3:$AA$2346,7,FALSE) -> tier - 2 | R6: =VLOOKUP($B6,'Answer Data Transformation'!$T$3:$AA$2346,8,FALSE) -> R1012 | S6: =VLOOKUP($B6,'Answer Data Transformation'!$T$3:$AA$2346,3,FALSE) -> 33
B7: Id6 | C7: =VLOOKUP(B7,'Answer Data Transformation'!$B$3:$F$2338,4,FALSE) -> Russell B | D7: =VLOOKUP($B7,'Answer Data Transformation'!$I$3:$R$2338,2,FALSE) -> 32.8 | E7: =VLOOKUP($B7,'Answer Data Transformation'!$I$3:$R$2338,4,FALSE) -> 6.59 | F7: =VLOOKUP($B7,'Answer Data Transformation'!$I$3:$R$2338,6,FALSE) -> No | G7: =VLOOKUP($B7,'Answer Data Transformation'!$I$3:$R$2338,7,FALSE) -> No | H7: =VLOOKUP($B7,'Answer Data Transformation'!$I$3:$R$2338,8,FALSE) -> No | I7: =VLOOKUP($B7,'Answer Data Transformation'!$I$3:$R$2338,9,FALSE) -> 0 | J7: =VLOOKUP($B7,'Answer Data Transformation'!$I$3:$R$2338,10,FALSE) -> Yes | K7: =VLOOKUP($B7,'Answer Data Transformation'!$I$3:$R$2338,3,FALSE) -> Obesity | L7: =VLOOKUP($B7,'Answer Data Transformation'!$I$3:$R$2338,5,FALSE) -> Diabetes | M7: =VLOOKUP($B7,'Answer Data Transformation'!$T$3:$AA$2346,2,FALSE) -> 04-Aug-1962 | N7: =VLOOKUP($B7,'Answer Data Transformation'!$T$3:$AA$2346,4,FALSE) -> 0 | O7: =VLOOKUP($B7,'Answer Data Transformation'!$T$3:$AA$2346,5,FALSE) -> 52590.83 | P7: =VLOOKUP($B7,'Answer Data Transformation'!$T$3:$AA$2346,6,FALSE) -> tier - 1 | Q7: =VLOOKUP($B7,'Answer Data Transformation'!$T$3:$AA$2346,7,FALSE) -> tier - 3 | R7: =VLOOKUP($B7,'Answer Data Transformation'!$T$3:$AA$2346,8,FALSE) -> R1011 | S7: =VLOOKUP($B7,'Answer Data Transformation'!$T$3:$AA$2346,3,FALSE) -> 60
